[2024-03-06T21:01:54.440+0000] {taskinstance.py:1956} INFO - Dependencies all met for dep_context=non-requeueable deps ti=<TaskInstance: weather_dag.transform_load_weather_data manual__2024-03-06T21:01:28.963049+00:00 [queued]>
[2024-03-06T21:01:54.450+0000] {taskinstance.py:1956} INFO - Dependencies all met for dep_context=requeueable deps ti=<TaskInstance: weather_dag.transform_load_weather_data manual__2024-03-06T21:01:28.963049+00:00 [queued]>
[2024-03-06T21:01:54.451+0000] {taskinstance.py:2170} INFO - Starting attempt 1 of 3
[2024-03-06T21:01:54.478+0000] {taskinstance.py:2191} INFO - Executing <Task(PythonOperator): transform_load_weather_data> on 2024-03-06 21:01:28.963049+00:00
[2024-03-06T21:01:54.510+0000] {standard_task_runner.py:60} INFO - Started process 2794 to run task
[2024-03-06T21:01:54.514+0000] {standard_task_runner.py:87} INFO - Running: ['***', 'tasks', 'run', 'weather_dag', 'transform_load_weather_data', 'manual__2024-03-06T21:01:28.963049+00:00', '--job-id', '142', '--raw', '--subdir', 'DAGS_FOLDER/weather_dag.py', '--cfg-path', '/tmp/tmp22n_0nl0']
[2024-03-06T21:01:54.516+0000] {standard_task_runner.py:88} INFO - Job 142: Subtask transform_load_weather_data
[2024-03-06T21:01:54.577+0000] {task_command.py:423} INFO - Running <TaskInstance: weather_dag.transform_load_weather_data manual__2024-03-06T21:01:28.963049+00:00 [running]> on host 5605ba714304
[2024-03-06T21:01:54.654+0000] {taskinstance.py:2480} INFO - Exporting env vars: AIRFLOW_CTX_DAG_EMAIL='myemail@domain.com' AIRFLOW_CTX_DAG_OWNER='***' AIRFLOW_CTX_DAG_ID='weather_dag' AIRFLOW_CTX_TASK_ID='transform_load_weather_data' AIRFLOW_CTX_EXECUTION_DATE='2024-03-06T21:01:28.963049+00:00' AIRFLOW_CTX_TRY_NUMBER='1' AIRFLOW_CTX_DAG_RUN_ID='manual__2024-03-06T21:01:28.963049+00:00'
[2024-03-06T21:01:54.656+0000] {logging_mixin.py:188} INFO - hello
[2024-03-06T21:01:54.941+0000] {logging_mixin.py:188} INFO -      City      Description  ...  Sunrise (Local Time)  Sunset (Local Time)
0  Passau  overcast clouds  ...   2024-03-06 06:37:35  2024-03-06 17:57:31

[1 rows x 12 columns]
[2024-03-06T21:01:54.942+0000] {taskinstance.py:2698} ERROR - Task failed with exception
Traceback (most recent call last):
  File "/home/airflow/.local/lib/python3.8/site-packages/airflow/models/taskinstance.py", line 433, in _execute_task
    result = execute_callable(context=context, **execute_callable_kwargs)
  File "/home/airflow/.local/lib/python3.8/site-packages/airflow/operators/python.py", line 199, in execute
    return_value = self.execute_callable()
  File "/home/airflow/.local/lib/python3.8/site-packages/airflow/operators/python.py", line 216, in execute_callable
    return self.python_callable(*self.op_args, **self.op_kwargs)
  File "/opt/airflow/dags/weather_TL.py", line 117, in transform_load_data
    os.chmod("D:\\CODE\\airflow\\data.csv", 0o777)
FileNotFoundError: [Errno 2] No such file or directory: 'D:\\CODE\\airflow\\data.csv'
[2024-03-06T21:01:54.957+0000] {taskinstance.py:1138} INFO - Marking task as UP_FOR_RETRY. dag_id=weather_dag, task_id=transform_load_weather_data, execution_date=20240306T210128, start_date=20240306T210154, end_date=20240306T210154
[2024-03-06T21:01:55.094+0000] {standard_task_runner.py:107} ERROR - Failed to execute job 142 for task transform_load_weather_data ([Errno 2] No such file or directory: 'D:\\CODE\\airflow\\data.csv'; 2794)
[2024-03-06T21:01:55.129+0000] {local_task_job_runner.py:234} INFO - Task exited with return code 1
[2024-03-06T21:01:55.146+0000] {taskinstance.py:3280} INFO - 0 downstream tasks scheduled from follow-on schedule check
