[2024-03-03T13:28:10.460+0000] {taskinstance.py:1956} INFO - Dependencies all met for dep_context=non-requeueable deps ti=<TaskInstance: weather_dag.is_weather_api_ready manual__2024-03-03T12:57:01.203099+00:00 [queued]>
[2024-03-03T13:28:10.474+0000] {taskinstance.py:1956} INFO - Dependencies all met for dep_context=requeueable deps ti=<TaskInstance: weather_dag.is_weather_api_ready manual__2024-03-03T12:57:01.203099+00:00 [queued]>
[2024-03-03T13:28:10.475+0000] {taskinstance.py:2170} INFO - Starting attempt 1 of 3
[2024-03-03T13:28:10.508+0000] {taskinstance.py:2191} INFO - Executing <Task(HttpSensor): is_weather_api_ready> on 2024-03-03 12:57:01.203099+00:00
[2024-03-03T13:28:10.524+0000] {standard_task_runner.py:60} INFO - Started process 110 to run task
[2024-03-03T13:28:10.530+0000] {standard_task_runner.py:87} INFO - Running: ['***', 'tasks', 'run', 'weather_dag', 'is_weather_api_ready', 'manual__2024-03-03T12:57:01.203099+00:00', '--job-id', '49', '--raw', '--subdir', 'DAGS_FOLDER/weather_dag.py', '--cfg-path', '/tmp/tmp8yub0nms']
[2024-03-03T13:28:10.535+0000] {standard_task_runner.py:88} INFO - Job 49: Subtask is_weather_api_ready
[2024-03-03T13:28:10.634+0000] {task_command.py:423} INFO - Running <TaskInstance: weather_dag.is_weather_api_ready manual__2024-03-03T12:57:01.203099+00:00 [running]> on host d3925ea582d2
[2024-03-03T13:28:10.744+0000] {taskinstance.py:2480} INFO - Exporting env vars: AIRFLOW_CTX_DAG_EMAIL='myemail@domain.com' AIRFLOW_CTX_DAG_OWNER='***' AIRFLOW_CTX_DAG_ID='weather_dag' AIRFLOW_CTX_TASK_ID='is_weather_api_ready' AIRFLOW_CTX_EXECUTION_DATE='2024-03-03T12:57:01.203099+00:00' AIRFLOW_CTX_TRY_NUMBER='1' AIRFLOW_CTX_DAG_RUN_ID='manual__2024-03-03T12:57:01.203099+00:00'
[2024-03-03T13:28:10.748+0000] {http.py:130} INFO - Poking: /data/2.5/weather?q=Passau&appid={9555a6fbad86a57efd0233c83b678fc3}
[2024-03-03T13:28:10.766+0000] {base.py:83} INFO - Using connection ID 'weathermap_api' for task execution.
[2024-03-03T13:28:11.833+0000] {http.py:178} ERROR - HTTP error: Unauthorized
[2024-03-03T13:28:11.834+0000] {http.py:179} ERROR - {"cod":401, "message": "Invalid API key. Please see https://openweathermap.org/faq#error401 for more info."}
[2024-03-03T13:28:11.846+0000] {taskinstance.py:2698} ERROR - Task failed with exception
Traceback (most recent call last):
  File "/home/airflow/.local/lib/python3.8/site-packages/airflow/providers/http/hooks/http.py", line 176, in check_response
    response.raise_for_status()
  File "/home/airflow/.local/lib/python3.8/site-packages/requests/models.py", line 1021, in raise_for_status
    raise HTTPError(http_error_msg, response=self)
requests.exceptions.HTTPError: 401 Client Error: Unauthorized for url: https://api.openweathermap.org/data/2.5/weather?q=Passau&appid=%7B9555a6fbad86a57efd0233c83b678fc3%7D

During handling of the above exception, another exception occurred:

Traceback (most recent call last):
  File "/home/airflow/.local/lib/python3.8/site-packages/airflow/models/taskinstance.py", line 433, in _execute_task
    result = execute_callable(context=context, **execute_callable_kwargs)
  File "/home/airflow/.local/lib/python3.8/site-packages/airflow/sensors/base.py", line 265, in execute
    raise e
  File "/home/airflow/.local/lib/python3.8/site-packages/airflow/sensors/base.py", line 247, in execute
    poke_return = self.poke(context)
  File "/home/airflow/.local/lib/python3.8/site-packages/airflow/providers/http/sensors/http.py", line 148, in poke
    raise exc
  File "/home/airflow/.local/lib/python3.8/site-packages/airflow/providers/http/sensors/http.py", line 132, in poke
    response = hook.run(
  File "/home/airflow/.local/lib/python3.8/site-packages/airflow/providers/http/hooks/http.py", line 166, in run
    return self.run_and_check(session, prepped_request, extra_options)
  File "/home/airflow/.local/lib/python3.8/site-packages/airflow/providers/http/hooks/http.py", line 217, in run_and_check
    self.check_response(response)
  File "/home/airflow/.local/lib/python3.8/site-packages/airflow/providers/http/hooks/http.py", line 180, in check_response
    raise AirflowException(str(response.status_code) + ":" + response.reason)
airflow.exceptions.AirflowException: 401:Unauthorized
[2024-03-03T13:28:11.851+0000] {taskinstance.py:1138} INFO - Marking task as UP_FOR_RETRY. dag_id=weather_dag, task_id=is_weather_api_ready, execution_date=20240303T125701, start_date=20240303T132810, end_date=20240303T132811
[2024-03-03T13:28:11.869+0000] {standard_task_runner.py:107} ERROR - Failed to execute job 49 for task is_weather_api_ready (401:Unauthorized; 110)
[2024-03-03T13:28:11.911+0000] {local_task_job_runner.py:234} INFO - Task exited with return code 1
[2024-03-03T13:28:11.942+0000] {taskinstance.py:3280} INFO - 0 downstream tasks scheduled from follow-on schedule check
