[2024-03-06T18:05:37.765+0000] {taskinstance.py:1956} INFO - Dependencies all met for dep_context=non-requeueable deps ti=<TaskInstance: weather_dag.extract_weather_data manual__2024-03-06T18:05:33.683907+00:00 [queued]>
[2024-03-06T18:05:37.776+0000] {taskinstance.py:1956} INFO - Dependencies all met for dep_context=requeueable deps ti=<TaskInstance: weather_dag.extract_weather_data manual__2024-03-06T18:05:33.683907+00:00 [queued]>
[2024-03-06T18:05:37.777+0000] {taskinstance.py:2170} INFO - Starting attempt 1 of 3
[2024-03-06T18:05:37.813+0000] {taskinstance.py:2191} INFO - Executing <Task(PythonOperator): extract_weather_data> on 2024-03-06 18:05:33.683907+00:00
[2024-03-06T18:05:37.820+0000] {standard_task_runner.py:60} INFO - Started process 276 to run task
[2024-03-06T18:05:37.824+0000] {standard_task_runner.py:87} INFO - Running: ['***', 'tasks', 'run', 'weather_dag', 'extract_weather_data', 'manual__2024-03-06T18:05:33.683907+00:00', '--job-id', '118', '--raw', '--subdir', 'DAGS_FOLDER/weather_dag.py', '--cfg-path', '/tmp/tmpbu0r5jxk']
[2024-03-06T18:05:37.825+0000] {standard_task_runner.py:88} INFO - Job 118: Subtask extract_weather_data
[2024-03-06T18:05:37.876+0000] {task_command.py:423} INFO - Running <TaskInstance: weather_dag.extract_weather_data manual__2024-03-06T18:05:33.683907+00:00 [running]> on host 5605ba714304
[2024-03-06T18:05:37.959+0000] {taskinstance.py:2480} INFO - Exporting env vars: AIRFLOW_CTX_DAG_EMAIL='myemail@domain.com' AIRFLOW_CTX_DAG_OWNER='***' AIRFLOW_CTX_DAG_ID='weather_dag' AIRFLOW_CTX_TASK_ID='extract_weather_data' AIRFLOW_CTX_EXECUTION_DATE='2024-03-06T18:05:33.683907+00:00' AIRFLOW_CTX_TRY_NUMBER='1' AIRFLOW_CTX_DAG_RUN_ID='manual__2024-03-06T18:05:33.683907+00:00'
[2024-03-06T18:05:37.962+0000] {taskinstance.py:2698} ERROR - Task failed with exception
Traceback (most recent call last):
  File "/home/airflow/.local/lib/python3.8/site-packages/airflow/models/taskinstance.py", line 433, in _execute_task
    result = execute_callable(context=context, **execute_callable_kwargs)
  File "/home/airflow/.local/lib/python3.8/site-packages/airflow/operators/python.py", line 199, in execute
    return_value = self.execute_callable()
  File "/home/airflow/.local/lib/python3.8/site-packages/airflow/operators/python.py", line 216, in execute_callable
    return self.python_callable(*self.op_args, **self.op_kwargs)
  File "/opt/airflow/dags/weather_TL.py", line 33, in extract_data
    with open("dags\weather_api_credentials.txt",'r') as f:
FileNotFoundError: [Errno 2] No such file or directory: 'dags\\weather_api_credentials.txt'
[2024-03-06T18:05:37.974+0000] {taskinstance.py:1138} INFO - Marking task as UP_FOR_RETRY. dag_id=weather_dag, task_id=extract_weather_data, execution_date=20240306T180533, start_date=20240306T180537, end_date=20240306T180537
[2024-03-06T18:05:37.987+0000] {standard_task_runner.py:107} ERROR - Failed to execute job 118 for task extract_weather_data ([Errno 2] No such file or directory: 'dags\\weather_api_credentials.txt'; 276)
[2024-03-06T18:05:38.037+0000] {local_task_job_runner.py:234} INFO - Task exited with return code 1
[2024-03-06T18:05:38.058+0000] {taskinstance.py:3280} INFO - 0 downstream tasks scheduled from follow-on schedule check
