[2024-03-06T18:26:17.272+0000] {taskinstance.py:1956} INFO - Dependencies all met for dep_context=non-requeueable deps ti=<TaskInstance: weather_dag.transform_load_weather_data manual__2024-03-06T18:21:53.732032+00:00 [queued]>
[2024-03-06T18:26:17.280+0000] {taskinstance.py:1956} INFO - Dependencies all met for dep_context=requeueable deps ti=<TaskInstance: weather_dag.transform_load_weather_data manual__2024-03-06T18:21:53.732032+00:00 [queued]>
[2024-03-06T18:26:17.281+0000] {taskinstance.py:2170} INFO - Starting attempt 2 of 3
[2024-03-06T18:26:17.296+0000] {taskinstance.py:2191} INFO - Executing <Task(PythonOperator): transform_load_weather_data> on 2024-03-06 18:21:53.732032+00:00
[2024-03-06T18:26:17.303+0000] {standard_task_runner.py:60} INFO - Started process 600 to run task
[2024-03-06T18:26:17.306+0000] {standard_task_runner.py:87} INFO - Running: ['***', 'tasks', 'run', 'weather_dag', 'transform_load_weather_data', 'manual__2024-03-06T18:21:53.732032+00:00', '--job-id', '129', '--raw', '--subdir', 'DAGS_FOLDER/weather_dag.py', '--cfg-path', '/tmp/tmp2ajz8cuz']
[2024-03-06T18:26:17.307+0000] {standard_task_runner.py:88} INFO - Job 129: Subtask transform_load_weather_data
[2024-03-06T18:26:17.348+0000] {task_command.py:423} INFO - Running <TaskInstance: weather_dag.transform_load_weather_data manual__2024-03-06T18:21:53.732032+00:00 [running]> on host 5605ba714304
[2024-03-06T18:26:17.416+0000] {taskinstance.py:2480} INFO - Exporting env vars: AIRFLOW_CTX_DAG_EMAIL='myemail@domain.com' AIRFLOW_CTX_DAG_OWNER='***' AIRFLOW_CTX_DAG_ID='weather_dag' AIRFLOW_CTX_TASK_ID='transform_load_weather_data' AIRFLOW_CTX_EXECUTION_DATE='2024-03-06T18:21:53.732032+00:00' AIRFLOW_CTX_TRY_NUMBER='2' AIRFLOW_CTX_DAG_RUN_ID='manual__2024-03-06T18:21:53.732032+00:00'
[2024-03-06T18:26:17.417+0000] {logging_mixin.py:188} INFO - hello
[2024-03-06T18:26:17.426+0000] {taskinstance.py:2698} ERROR - Task failed with exception
Traceback (most recent call last):
  File "/home/airflow/.local/lib/python3.8/site-packages/airflow/models/taskinstance.py", line 433, in _execute_task
    result = execute_callable(context=context, **execute_callable_kwargs)
  File "/home/airflow/.local/lib/python3.8/site-packages/airflow/operators/python.py", line 199, in execute
    return_value = self.execute_callable()
  File "/home/airflow/.local/lib/python3.8/site-packages/airflow/operators/python.py", line 216, in execute_callable
    return self.python_callable(*self.op_args, **self.op_kwargs)
  File "/opt/airflow/dags/weather_TL.py", line 69, in transform_load_data
    city= data["name"]
TypeError: list indices must be integers or slices, not str
[2024-03-06T18:26:17.436+0000] {taskinstance.py:1138} INFO - Marking task as UP_FOR_RETRY. dag_id=weather_dag, task_id=transform_load_weather_data, execution_date=20240306T182153, start_date=20240306T182617, end_date=20240306T182617
[2024-03-06T18:26:17.447+0000] {standard_task_runner.py:107} ERROR - Failed to execute job 129 for task transform_load_weather_data (list indices must be integers or slices, not str; 600)
[2024-03-06T18:26:17.479+0000] {local_task_job_runner.py:234} INFO - Task exited with return code 1
[2024-03-06T18:26:17.508+0000] {taskinstance.py:3280} INFO - 0 downstream tasks scheduled from follow-on schedule check
