[2024-03-06T18:28:18.977+0000] {taskinstance.py:1956} INFO - Dependencies all met for dep_context=non-requeueable deps ti=<TaskInstance: weather_dag.transform_load_weather_data manual__2024-03-06T18:21:53.732032+00:00 [queued]>
[2024-03-06T18:28:18.989+0000] {taskinstance.py:1956} INFO - Dependencies all met for dep_context=requeueable deps ti=<TaskInstance: weather_dag.transform_load_weather_data manual__2024-03-06T18:21:53.732032+00:00 [queued]>
[2024-03-06T18:28:18.989+0000] {taskinstance.py:2170} INFO - Starting attempt 3 of 3
[2024-03-06T18:28:19.000+0000] {taskinstance.py:2191} INFO - Executing <Task(PythonOperator): transform_load_weather_data> on 2024-03-06 18:21:53.732032+00:00
[2024-03-06T18:28:19.010+0000] {standard_task_runner.py:60} INFO - Started process 635 to run task
[2024-03-06T18:28:19.013+0000] {standard_task_runner.py:87} INFO - Running: ['***', 'tasks', 'run', 'weather_dag', 'transform_load_weather_data', 'manual__2024-03-06T18:21:53.732032+00:00', '--job-id', '130', '--raw', '--subdir', 'DAGS_FOLDER/weather_dag.py', '--cfg-path', '/tmp/tmp6tl5rc7m']
[2024-03-06T18:28:19.014+0000] {standard_task_runner.py:88} INFO - Job 130: Subtask transform_load_weather_data
[2024-03-06T18:28:19.060+0000] {task_command.py:423} INFO - Running <TaskInstance: weather_dag.transform_load_weather_data manual__2024-03-06T18:21:53.732032+00:00 [running]> on host 5605ba714304
[2024-03-06T18:28:19.148+0000] {taskinstance.py:2480} INFO - Exporting env vars: AIRFLOW_CTX_DAG_EMAIL='myemail@domain.com' AIRFLOW_CTX_DAG_OWNER='***' AIRFLOW_CTX_DAG_ID='weather_dag' AIRFLOW_CTX_TASK_ID='transform_load_weather_data' AIRFLOW_CTX_EXECUTION_DATE='2024-03-06T18:21:53.732032+00:00' AIRFLOW_CTX_TRY_NUMBER='3' AIRFLOW_CTX_DAG_RUN_ID='manual__2024-03-06T18:21:53.732032+00:00'
[2024-03-06T18:28:19.152+0000] {logging_mixin.py:188} INFO - hello
[2024-03-06T18:28:19.162+0000] {taskinstance.py:2698} ERROR - Task failed with exception
Traceback (most recent call last):
  File "/home/airflow/.local/lib/python3.8/site-packages/airflow/models/taskinstance.py", line 433, in _execute_task
    result = execute_callable(context=context, **execute_callable_kwargs)
  File "/home/airflow/.local/lib/python3.8/site-packages/airflow/operators/python.py", line 199, in execute
    return_value = self.execute_callable()
  File "/home/airflow/.local/lib/python3.8/site-packages/airflow/operators/python.py", line 216, in execute_callable
    return self.python_callable(*self.op_args, **self.op_kwargs)
  File "/opt/airflow/dags/weather_TL.py", line 69, in transform_load_data
    city= data["name"]
TypeError: list indices must be integers or slices, not str
[2024-03-06T18:28:19.176+0000] {taskinstance.py:1138} INFO - Marking task as FAILED. dag_id=weather_dag, task_id=transform_load_weather_data, execution_date=20240306T182153, start_date=20240306T182818, end_date=20240306T182819
[2024-03-06T18:28:19.189+0000] {standard_task_runner.py:107} ERROR - Failed to execute job 130 for task transform_load_weather_data (list indices must be integers or slices, not str; 635)
[2024-03-06T18:28:19.225+0000] {local_task_job_runner.py:234} INFO - Task exited with return code 1
[2024-03-06T18:28:19.241+0000] {taskinstance.py:3280} INFO - 0 downstream tasks scheduled from follow-on schedule check
